[2025-04-12T12:16:32.587+0000] {taskinstance.py:1956} INFO - Dependencies all met for dep_context=non-requeueable deps ti=<TaskInstance: weekly_comment_analysis_pipeline.fetch_recent_comments manual__2025-04-12T12:16:28.160260+00:00 [queued]>
[2025-04-12T12:16:32.591+0000] {taskinstance.py:1956} INFO - Dependencies all met for dep_context=requeueable deps ti=<TaskInstance: weekly_comment_analysis_pipeline.fetch_recent_comments manual__2025-04-12T12:16:28.160260+00:00 [queued]>
[2025-04-12T12:16:32.591+0000] {taskinstance.py:2170} INFO - Starting attempt 1 of 1
[2025-04-12T12:16:32.597+0000] {taskinstance.py:2191} INFO - Executing <Task(PythonOperator): fetch_recent_comments> on 2025-04-12 12:16:28.160260+00:00
[2025-04-12T12:16:32.603+0000] {standard_task_runner.py:60} INFO - Started process 366 to run task
[2025-04-12T12:16:32.605+0000] {standard_task_runner.py:87} INFO - Running: ['***', 'tasks', 'run', 'weekly_comment_analysis_pipeline', 'fetch_recent_comments', 'manual__2025-04-12T12:16:28.160260+00:00', '--job-id', '222', '--raw', '--subdir', 'DAGS_FOLDER/Sentiment_Topicmodelling.py', '--cfg-path', '/tmp/tmpnuij7r8a']
[2025-04-12T12:16:32.606+0000] {standard_task_runner.py:88} INFO - Job 222: Subtask fetch_recent_comments
[2025-04-12T12:16:32.632+0000] {task_command.py:423} INFO - Running <TaskInstance: weekly_comment_analysis_pipeline.fetch_recent_comments manual__2025-04-12T12:16:28.160260+00:00 [running]> on host 09c1abf4dbfb
[2025-04-12T12:16:32.676+0000] {taskinstance.py:2480} INFO - Exporting env vars: AIRFLOW_CTX_DAG_OWNER='***' AIRFLOW_CTX_DAG_ID='weekly_comment_analysis_pipeline' AIRFLOW_CTX_TASK_ID='fetch_recent_comments' AIRFLOW_CTX_EXECUTION_DATE='2025-04-12T12:16:28.160260+00:00' AIRFLOW_CTX_TRY_NUMBER='1' AIRFLOW_CTX_DAG_RUN_ID='manual__2025-04-12T12:16:28.160260+00:00'
[2025-04-12T12:16:32.680+0000] {logging_mixin.py:188} WARNING - /home/***/.local/lib/python3.8/site-packages/***/utils/context.py:315 AirflowContextDeprecationWarning: Accessing 'execution_date' from the template is deprecated and will be removed in a future version. Please use 'data_interval_start' or 'logical_date' instead.
[2025-04-12T12:16:32.694+0000] {base.py:83} INFO - Using connection ID 'aws_pg' for task execution.
[2025-04-12T12:17:48.071+0000] {taskinstance.py:2698} ERROR - Task failed with exception
Traceback (most recent call last):
  File "/home/airflow/.local/lib/python3.8/site-packages/airflow/models/taskinstance.py", line 433, in _execute_task
    result = execute_callable(context=context, **execute_callable_kwargs)
  File "/home/airflow/.local/lib/python3.8/site-packages/airflow/operators/python.py", line 199, in execute
    return_value = self.execute_callable()
  File "/home/airflow/.local/lib/python3.8/site-packages/airflow/operators/python.py", line 216, in execute_callable
    return self.python_callable(*self.op_args, **self.op_kwargs)
  File "/opt/airflow/dags/Sentiment_Topicmodelling.py", line 25, in fetch_recent_comments
    conn = hook.get_conn()
  File "/home/airflow/.local/lib/python3.8/site-packages/airflow/providers/postgres/hooks/postgres.py", line 158, in get_conn
    self.conn = psycopg2.connect(**conn_args)
  File "/home/airflow/.local/lib/python3.8/site-packages/psycopg2/__init__.py", line 122, in connect
    conn = _connect(dsn, connection_factory=connection_factory, **kwasync)
psycopg2.OperationalError: connection to server at "database-1.cb0kcw8qg146.us-east-1.rds.amazonaws.com" (3.213.99.62), port 5432 failed: Connection refused
	Is the server running on that host and accepting TCP/IP connections?

[2025-04-12T12:17:48.093+0000] {taskinstance.py:1138} INFO - Marking task as FAILED. dag_id=weekly_comment_analysis_pipeline, task_id=fetch_recent_comments, execution_date=20250412T121628, start_date=20250412T121632, end_date=20250412T121748
[2025-04-12T12:17:48.100+0000] {standard_task_runner.py:107} ERROR - Failed to execute job 222 for task fetch_recent_comments (connection to server at "database-1.cb0kcw8qg146.us-east-1.rds.amazonaws.com" (3.213.99.62), port 5432 failed: Connection refused
	Is the server running on that host and accepting TCP/IP connections?
; 366)
[2025-04-12T12:17:48.131+0000] {local_task_job_runner.py:234} INFO - Task exited with return code 1
[2025-04-12T12:17:48.145+0000] {taskinstance.py:3280} INFO - 0 downstream tasks scheduled from follow-on schedule check
