[2025-04-08T00:14:21.134+0000] {taskinstance.py:1956} INFO - Dependencies all met for dep_context=non-requeueable deps ti=<TaskInstance: youtube_comment_pipeline_us_stocks_daily.search_youtube scheduled__2025-04-07T00:00:00+00:00 [queued]>
[2025-04-08T00:14:21.155+0000] {taskinstance.py:1956} INFO - Dependencies all met for dep_context=requeueable deps ti=<TaskInstance: youtube_comment_pipeline_us_stocks_daily.search_youtube scheduled__2025-04-07T00:00:00+00:00 [queued]>
[2025-04-08T00:14:21.156+0000] {taskinstance.py:2170} INFO - Starting attempt 1 of 1
[2025-04-08T00:14:21.182+0000] {taskinstance.py:2191} INFO - Executing <Task(PythonOperator): search_youtube> on 2025-04-07 00:00:00+00:00
[2025-04-08T00:14:21.193+0000] {standard_task_runner.py:60} INFO - Started process 6450 to run task
[2025-04-08T00:14:21.198+0000] {standard_task_runner.py:87} INFO - Running: ['***', 'tasks', 'run', 'youtube_comment_pipeline_us_stocks_daily', 'search_youtube', 'scheduled__2025-04-07T00:00:00+00:00', '--job-id', '164', '--raw', '--subdir', 'DAGS_FOLDER/youtube_comment_pipeline.py', '--cfg-path', '/tmp/tmpsq5ocf2d']
[2025-04-08T00:14:21.200+0000] {standard_task_runner.py:88} INFO - Job 164: Subtask search_youtube
[2025-04-08T00:14:21.272+0000] {task_command.py:423} INFO - Running <TaskInstance: youtube_comment_pipeline_us_stocks_daily.search_youtube scheduled__2025-04-07T00:00:00+00:00 [running]> on host 288775c8919d
[2025-04-08T00:14:21.343+0000] {taskinstance.py:2480} INFO - Exporting env vars: AIRFLOW_CTX_DAG_OWNER='***' AIRFLOW_CTX_DAG_ID='youtube_comment_pipeline_us_stocks_daily' AIRFLOW_CTX_TASK_ID='search_youtube' AIRFLOW_CTX_EXECUTION_DATE='2025-04-07T00:00:00+00:00' AIRFLOW_CTX_TRY_NUMBER='1' AIRFLOW_CTX_DAG_RUN_ID='scheduled__2025-04-07T00:00:00+00:00'
[2025-04-08T00:14:21.353+0000] {taskinstance.py:2698} ERROR - Task failed with exception
Traceback (most recent call last):
  File "/home/airflow/.local/lib/python3.8/site-packages/urllib3/connection.py", line 174, in _new_conn
    conn = connection.create_connection(
  File "/home/airflow/.local/lib/python3.8/site-packages/urllib3/util/connection.py", line 72, in create_connection
    for res in socket.getaddrinfo(host, port, family, socket.SOCK_STREAM):
  File "/usr/local/lib/python3.8/socket.py", line 918, in getaddrinfo
    for res in _socket.getaddrinfo(host, port, family, type, proto, flags):
socket.gaierror: [Errno -2] Name or service not known

During handling of the above exception, another exception occurred:

Traceback (most recent call last):
  File "/home/airflow/.local/lib/python3.8/site-packages/urllib3/connectionpool.py", line 715, in urlopen
    httplib_response = self._make_request(
  File "/home/airflow/.local/lib/python3.8/site-packages/urllib3/connectionpool.py", line 404, in _make_request
    self._validate_conn(conn)
  File "/home/airflow/.local/lib/python3.8/site-packages/urllib3/connectionpool.py", line 1058, in _validate_conn
    conn.connect()
  File "/home/airflow/.local/lib/python3.8/site-packages/urllib3/connection.py", line 363, in connect
    self.sock = conn = self._new_conn()
  File "/home/airflow/.local/lib/python3.8/site-packages/urllib3/connection.py", line 186, in _new_conn
    raise NewConnectionError(
urllib3.exceptions.NewConnectionError: <urllib3.connection.HTTPSConnection object at 0xffff96f6bbe0>: Failed to establish a new connection: [Errno -2] Name or service not known

During handling of the above exception, another exception occurred:

Traceback (most recent call last):
  File "/home/airflow/.local/lib/python3.8/site-packages/requests/adapters.py", line 486, in send
    resp = conn.urlopen(
  File "/home/airflow/.local/lib/python3.8/site-packages/urllib3/connectionpool.py", line 799, in urlopen
    retries = retries.increment(
  File "/home/airflow/.local/lib/python3.8/site-packages/urllib3/util/retry.py", line 592, in increment
    raise MaxRetryError(_pool, url, error or ResponseError(cause))
urllib3.exceptions.MaxRetryError: HTTPSConnectionPool(host='www.googleapis.com', port=443): Max retries exceeded with url: /youtube/v3/search?key=AIzaSyCqdWn1WKWzcWYOtEiXFdYzBk0E_m85QXE&q=us+stocks&part=snippet&type=video&maxResults=40 (Caused by NewConnectionError('<urllib3.connection.HTTPSConnection object at 0xffff96f6bbe0>: Failed to establish a new connection: [Errno -2] Name or service not known'))

During handling of the above exception, another exception occurred:

Traceback (most recent call last):
  File "/home/airflow/.local/lib/python3.8/site-packages/airflow/models/taskinstance.py", line 433, in _execute_task
    result = execute_callable(context=context, **execute_callable_kwargs)
  File "/home/airflow/.local/lib/python3.8/site-packages/airflow/operators/python.py", line 199, in execute
    return_value = self.execute_callable()
  File "/home/airflow/.local/lib/python3.8/site-packages/airflow/operators/python.py", line 216, in execute_callable
    return self.python_callable(*self.op_args, **self.op_kwargs)
  File "/opt/airflow/dags/youtube_comment_pipeline.py", line 28, in search_youtube
    res = requests.get(url, params=params).json()
  File "/home/airflow/.local/lib/python3.8/site-packages/requests/api.py", line 73, in get
    return request("get", url, params=params, **kwargs)
  File "/home/airflow/.local/lib/python3.8/site-packages/requests/api.py", line 59, in request
    return session.request(method=method, url=url, **kwargs)
  File "/home/airflow/.local/lib/python3.8/site-packages/requests/sessions.py", line 589, in request
    resp = self.send(prep, **send_kwargs)
  File "/home/airflow/.local/lib/python3.8/site-packages/requests/sessions.py", line 703, in send
    r = adapter.send(request, **kwargs)
  File "/home/airflow/.local/lib/python3.8/site-packages/requests/adapters.py", line 519, in send
    raise ConnectionError(e, request=request)
requests.exceptions.ConnectionError: HTTPSConnectionPool(host='www.googleapis.com', port=443): Max retries exceeded with url: /youtube/v3/search?key=AIzaSyCqdWn1WKWzcWYOtEiXFdYzBk0E_m85QXE&q=us+stocks&part=snippet&type=video&maxResults=40 (Caused by NewConnectionError('<urllib3.connection.HTTPSConnection object at 0xffff96f6bbe0>: Failed to establish a new connection: [Errno -2] Name or service not known'))
[2025-04-08T00:14:21.362+0000] {taskinstance.py:1138} INFO - Marking task as FAILED. dag_id=youtube_comment_pipeline_us_stocks_daily, task_id=search_youtube, execution_date=20250407T000000, start_date=20250408T001421, end_date=20250408T001421
[2025-04-08T00:14:21.369+0000] {standard_task_runner.py:107} ERROR - Failed to execute job 164 for task search_youtube (HTTPSConnectionPool(host='www.googleapis.com', port=443): Max retries exceeded with url: /youtube/v3/search?key=AIzaSyCqdWn1WKWzcWYOtEiXFdYzBk0E_m85QXE&q=us+stocks&part=snippet&type=video&maxResults=40 (Caused by NewConnectionError('<urllib3.connection.HTTPSConnection object at 0xffff96f6bbe0>: Failed to establish a new connection: [Errno -2] Name or service not known')); 6450)
[2025-04-08T00:14:21.376+0000] {local_task_job_runner.py:234} INFO - Task exited with return code 1
[2025-04-08T00:14:21.389+0000] {taskinstance.py:3280} INFO - 0 downstream tasks scheduled from follow-on schedule check
[2025-04-20T02:24:43.131+0000] {taskinstance.py:1956} INFO - Dependencies all met for dep_context=non-requeueable deps ti=<TaskInstance: youtube_comment_pipeline_us_stocks_daily.search_youtube scheduled__2025-04-07T00:00:00+00:00 [queued]>
[2025-04-20T02:24:43.145+0000] {taskinstance.py:1956} INFO - Dependencies all met for dep_context=requeueable deps ti=<TaskInstance: youtube_comment_pipeline_us_stocks_daily.search_youtube scheduled__2025-04-07T00:00:00+00:00 [queued]>
[2025-04-20T02:24:43.145+0000] {taskinstance.py:2170} INFO - Starting attempt 1 of 1
[2025-04-20T02:24:43.163+0000] {taskinstance.py:2191} INFO - Executing <Task(PythonOperator): search_youtube> on 2025-04-07 00:00:00+00:00
[2025-04-20T02:24:43.166+0000] {standard_task_runner.py:60} INFO - Started process 2140 to run task
[2025-04-20T02:24:43.172+0000] {standard_task_runner.py:87} INFO - Running: ['***', 'tasks', 'run', 'youtube_comment_pipeline_us_stocks_daily', 'search_youtube', 'scheduled__2025-04-07T00:00:00+00:00', '--job-id', '518', '--raw', '--subdir', 'DAGS_FOLDER/youtube_comment_pipeline.py', '--cfg-path', '/tmp/tmpnroc7ec8']
[2025-04-20T02:24:43.173+0000] {standard_task_runner.py:88} INFO - Job 518: Subtask search_youtube
[2025-04-20T02:24:43.229+0000] {task_command.py:423} INFO - Running <TaskInstance: youtube_comment_pipeline_us_stocks_daily.search_youtube scheduled__2025-04-07T00:00:00+00:00 [running]> on host 7e480c288e12
[2025-04-20T02:24:43.355+0000] {taskinstance.py:2480} INFO - Exporting env vars: AIRFLOW_CTX_DAG_OWNER='***' AIRFLOW_CTX_DAG_ID='youtube_comment_pipeline_us_stocks_daily' AIRFLOW_CTX_TASK_ID='search_youtube' AIRFLOW_CTX_EXECUTION_DATE='2025-04-07T00:00:00+00:00' AIRFLOW_CTX_TRY_NUMBER='1' AIRFLOW_CTX_DAG_RUN_ID='scheduled__2025-04-07T00:00:00+00:00'
[2025-04-20T02:24:44.106+0000] {python.py:201} INFO - Done. Returned value was: None
[2025-04-20T02:24:44.134+0000] {taskinstance.py:1138} INFO - Marking task as SUCCESS. dag_id=youtube_comment_pipeline_us_stocks_daily, task_id=search_youtube, execution_date=20250407T000000, start_date=20250420T022443, end_date=20250420T022444
[2025-04-20T02:24:44.301+0000] {local_task_job_runner.py:234} INFO - Task exited with return code 0
[2025-04-20T02:24:44.355+0000] {taskinstance.py:3280} INFO - 1 downstream tasks scheduled from follow-on schedule check
