[2025-04-12T16:13:22.454+0000] {taskinstance.py:1956} INFO - Dependencies all met for dep_context=non-requeueable deps ti=<TaskInstance: weekly_comment_analysis_pipeline.save_processed_comments manual__2025-04-12T16:11:31.295673+00:00 [queued]>
[2025-04-12T16:13:22.473+0000] {taskinstance.py:1956} INFO - Dependencies all met for dep_context=requeueable deps ti=<TaskInstance: weekly_comment_analysis_pipeline.save_processed_comments manual__2025-04-12T16:11:31.295673+00:00 [queued]>
[2025-04-12T16:13:22.473+0000] {taskinstance.py:2170} INFO - Starting attempt 1 of 1
[2025-04-12T16:13:22.490+0000] {taskinstance.py:2191} INFO - Executing <Task(PythonOperator): save_processed_comments> on 2025-04-12 16:11:31.295673+00:00
[2025-04-12T16:13:22.499+0000] {standard_task_runner.py:60} INFO - Started process 48898 to run task
[2025-04-12T16:13:22.503+0000] {standard_task_runner.py:87} INFO - Running: ['***', 'tasks', 'run', 'weekly_comment_analysis_pipeline', 'save_processed_comments', 'manual__2025-04-12T16:11:31.295673+00:00', '--job-id', '269', '--raw', '--subdir', 'DAGS_FOLDER/Sentiment_Topicmodelling.py', '--cfg-path', '/tmp/tmpu35k68xq']
[2025-04-12T16:13:22.507+0000] {standard_task_runner.py:88} INFO - Job 269: Subtask save_processed_comments
[2025-04-12T16:13:22.573+0000] {task_command.py:423} INFO - Running <TaskInstance: weekly_comment_analysis_pipeline.save_processed_comments manual__2025-04-12T16:11:31.295673+00:00 [running]> on host b22c3b1dd6e4
[2025-04-12T16:13:22.659+0000] {taskinstance.py:2480} INFO - Exporting env vars: AIRFLOW_CTX_DAG_OWNER='***' AIRFLOW_CTX_DAG_ID='weekly_comment_analysis_pipeline' AIRFLOW_CTX_TASK_ID='save_processed_comments' AIRFLOW_CTX_EXECUTION_DATE='2025-04-12T16:11:31.295673+00:00' AIRFLOW_CTX_TRY_NUMBER='1' AIRFLOW_CTX_DAG_RUN_ID='manual__2025-04-12T16:11:31.295673+00:00'
[2025-04-12T16:13:22.694+0000] {base.py:83} INFO - Using connection ID 'aws_pg' for task execution.
[2025-04-12T16:13:27.827+0000] {taskinstance.py:2698} ERROR - Task failed with exception
Traceback (most recent call last):
  File "/home/airflow/.local/lib/python3.8/site-packages/airflow/models/taskinstance.py", line 433, in _execute_task
    result = execute_callable(context=context, **execute_callable_kwargs)
  File "/home/airflow/.local/lib/python3.8/site-packages/airflow/operators/python.py", line 199, in execute
    return_value = self.execute_callable()
  File "/home/airflow/.local/lib/python3.8/site-packages/airflow/operators/python.py", line 216, in execute_callable
    return self.python_callable(*self.op_args, **self.op_kwargs)
  File "/opt/airflow/dags/Sentiment_Topicmodelling.py", line 112, in save_processed_comments
    values = [
TypeError: 'NoneType' object is not iterable
[2025-04-12T16:13:27.837+0000] {taskinstance.py:1138} INFO - Marking task as FAILED. dag_id=weekly_comment_analysis_pipeline, task_id=save_processed_comments, execution_date=20250412T161131, start_date=20250412T161322, end_date=20250412T161327
[2025-04-12T16:13:27.846+0000] {standard_task_runner.py:107} ERROR - Failed to execute job 269 for task save_processed_comments ('NoneType' object is not iterable; 48898)
[2025-04-12T16:13:27.861+0000] {local_task_job_runner.py:234} INFO - Task exited with return code 1
[2025-04-12T16:13:27.874+0000] {taskinstance.py:3280} INFO - 0 downstream tasks scheduled from follow-on schedule check
