[2025-04-14T08:00:02.689+0000] {taskinstance.py:1956} INFO - Dependencies all met for dep_context=non-requeueable deps ti=<TaskInstance: youtube_comment_pipeline_us_stocks_daily.filter_with_openai scheduled__2025-04-13T08:00:00+00:00 [queued]>
[2025-04-14T08:00:02.691+0000] {taskinstance.py:1956} INFO - Dependencies all met for dep_context=requeueable deps ti=<TaskInstance: youtube_comment_pipeline_us_stocks_daily.filter_with_openai scheduled__2025-04-13T08:00:00+00:00 [queued]>
[2025-04-14T08:00:02.691+0000] {taskinstance.py:2170} INFO - Starting attempt 1 of 1
[2025-04-14T08:00:02.695+0000] {taskinstance.py:2191} INFO - Executing <Task(PythonOperator): filter_with_openai> on 2025-04-13 08:00:00+00:00
[2025-04-14T08:00:02.698+0000] {standard_task_runner.py:60} INFO - Started process 8647 to run task
[2025-04-14T08:00:02.700+0000] {standard_task_runner.py:87} INFO - Running: ['***', 'tasks', 'run', 'youtube_comment_pipeline_us_stocks_daily', 'filter_with_openai', 'scheduled__2025-04-13T08:00:00+00:00', '--job-id', '417', '--raw', '--subdir', 'DAGS_FOLDER/youtube_comment_pipeline.py', '--cfg-path', '/tmp/tmp15_h5xh2']
[2025-04-14T08:00:02.701+0000] {standard_task_runner.py:88} INFO - Job 417: Subtask filter_with_openai
[2025-04-14T08:00:02.719+0000] {task_command.py:423} INFO - Running <TaskInstance: youtube_comment_pipeline_us_stocks_daily.filter_with_openai scheduled__2025-04-13T08:00:00+00:00 [running]> on host 9d8a82da5923
[2025-04-14T08:00:02.750+0000] {taskinstance.py:2480} INFO - Exporting env vars: AIRFLOW_CTX_DAG_OWNER='***' AIRFLOW_CTX_DAG_ID='youtube_comment_pipeline_us_stocks_daily' AIRFLOW_CTX_TASK_ID='filter_with_openai' AIRFLOW_CTX_EXECUTION_DATE='2025-04-13T08:00:00+00:00' AIRFLOW_CTX_TRY_NUMBER='1' AIRFLOW_CTX_DAG_RUN_ID='scheduled__2025-04-13T08:00:00+00:00'
[2025-04-14T08:21:16.669+0000] {local_task_job_runner.py:302} WARNING - State of this instance has been externally set to failed. Terminating instance.
[2025-04-14T08:21:16.672+0000] {process_utils.py:131} INFO - Sending 15 to group 8647. PIDs of all processes in the group: [8647]
[2025-04-14T08:21:16.672+0000] {process_utils.py:86} INFO - Sending the signal 15 to group 8647
[2025-04-14T08:21:16.673+0000] {taskinstance.py:2450} ERROR - Received SIGTERM. Terminating subprocesses.
[2025-04-14T08:21:16.674+0000] {_base_client.py:1051} INFO - Retrying request to /chat/completions in 0.402903 seconds
[2025-04-14T08:21:17.091+0000] {_base_client.py:1051} INFO - Retrying request to /chat/completions in 0.793550 seconds
[2025-04-14T08:21:17.903+0000] {taskinstance.py:2698} ERROR - Task failed with exception
Traceback (most recent call last):
  File "/home/airflow/.local/lib/python3.8/site-packages/openai/_base_client.py", line 955, in _request
    response = self._client.send(
  File "/home/airflow/.local/lib/python3.8/site-packages/httpx/_client.py", line 908, in send
    response = self._send_handling_auth(
  File "/home/airflow/.local/lib/python3.8/site-packages/httpx/_client.py", line 936, in _send_handling_auth
    response = self._send_handling_redirects(
  File "/home/airflow/.local/lib/python3.8/site-packages/httpx/_client.py", line 973, in _send_handling_redirects
    response = self._send_single_request(request)
  File "/home/airflow/.local/lib/python3.8/site-packages/httpx/_client.py", line 1009, in _send_single_request
    response = transport.handle_request(request)
  File "/home/airflow/.local/lib/python3.8/site-packages/httpx/_transports/default.py", line 218, in handle_request
    resp = self._pool.handle_request(req)
  File "/home/airflow/.local/lib/python3.8/site-packages/httpcore/_sync/connection_pool.py", line 253, in handle_request
    raise exc
  File "/home/airflow/.local/lib/python3.8/site-packages/httpcore/_sync/connection_pool.py", line 237, in handle_request
    response = connection.handle_request(request)
  File "/home/airflow/.local/lib/python3.8/site-packages/httpcore/_sync/connection.py", line 90, in handle_request
    return self._connection.handle_request(request)
  File "/home/airflow/.local/lib/python3.8/site-packages/httpcore/_sync/http11.py", line 112, in handle_request
    raise exc
  File "/home/airflow/.local/lib/python3.8/site-packages/httpcore/_sync/http11.py", line 91, in handle_request
    ) = self._receive_response_headers(**kwargs)
  File "/home/airflow/.local/lib/python3.8/site-packages/httpcore/_sync/http11.py", line 155, in _receive_response_headers
    event = self._receive_event(timeout=timeout)
  File "/home/airflow/.local/lib/python3.8/site-packages/httpcore/_sync/http11.py", line 191, in _receive_event
    data = self._network_stream.read(
  File "/home/airflow/.local/lib/python3.8/site-packages/httpcore/backends/sync.py", line 28, in read
    return self._sock.recv(max_bytes)
  File "/usr/local/lib/python3.8/ssl.py", line 1259, in recv
    return self.read(buflen)
  File "/usr/local/lib/python3.8/ssl.py", line 1134, in read
    return self._sslobj.read(len)
  File "/home/airflow/.local/lib/python3.8/site-packages/airflow/models/taskinstance.py", line 2452, in signal_handler
    raise AirflowException("Task received SIGTERM signal")
airflow.exceptions.AirflowException: Task received SIGTERM signal

During handling of the above exception, another exception occurred:

Traceback (most recent call last):
  File "/home/airflow/.local/lib/python3.8/site-packages/httpcore/_exceptions.py", line 10, in map_exceptions
    yield
  File "/home/airflow/.local/lib/python3.8/site-packages/httpcore/backends/sync.py", line 94, in connect_tcp
    sock = socket.create_connection(
  File "/usr/local/lib/python3.8/socket.py", line 787, in create_connection
    for res in getaddrinfo(host, port, 0, SOCK_STREAM):
  File "/usr/local/lib/python3.8/socket.py", line 918, in getaddrinfo
    for res in _socket.getaddrinfo(host, port, family, type, proto, flags):
socket.gaierror: [Errno -2] Name or service not known

During handling of the above exception, another exception occurred:

Traceback (most recent call last):
  File "/home/airflow/.local/lib/python3.8/site-packages/httpx/_transports/default.py", line 60, in map_httpcore_exceptions
    yield
  File "/home/airflow/.local/lib/python3.8/site-packages/httpx/_transports/default.py", line 218, in handle_request
    resp = self._pool.handle_request(req)
  File "/home/airflow/.local/lib/python3.8/site-packages/httpcore/_sync/connection_pool.py", line 253, in handle_request
    raise exc
  File "/home/airflow/.local/lib/python3.8/site-packages/httpcore/_sync/connection_pool.py", line 237, in handle_request
    response = connection.handle_request(request)
  File "/home/airflow/.local/lib/python3.8/site-packages/httpcore/_sync/connection.py", line 86, in handle_request
    raise exc
  File "/home/airflow/.local/lib/python3.8/site-packages/httpcore/_sync/connection.py", line 63, in handle_request
    stream = self._connect(request)
  File "/home/airflow/.local/lib/python3.8/site-packages/httpcore/_sync/connection.py", line 111, in _connect
    stream = self._network_backend.connect_tcp(**kwargs)
  File "/home/airflow/.local/lib/python3.8/site-packages/httpcore/backends/sync.py", line 94, in connect_tcp
    sock = socket.create_connection(
  File "/usr/local/lib/python3.8/contextlib.py", line 131, in __exit__
    self.gen.throw(type, value, traceback)
  File "/home/airflow/.local/lib/python3.8/site-packages/httpcore/_exceptions.py", line 14, in map_exceptions
    raise to_exc(exc)
httpcore.ConnectError: [Errno -2] Name or service not known

The above exception was the direct cause of the following exception:

Traceback (most recent call last):
  File "/home/airflow/.local/lib/python3.8/site-packages/openai/_base_client.py", line 955, in _request
    response = self._client.send(
  File "/home/airflow/.local/lib/python3.8/site-packages/httpx/_client.py", line 908, in send
    response = self._send_handling_auth(
  File "/home/airflow/.local/lib/python3.8/site-packages/httpx/_client.py", line 936, in _send_handling_auth
    response = self._send_handling_redirects(
  File "/home/airflow/.local/lib/python3.8/site-packages/httpx/_client.py", line 973, in _send_handling_redirects
    response = self._send_single_request(request)
  File "/home/airflow/.local/lib/python3.8/site-packages/httpx/_client.py", line 1009, in _send_single_request
    response = transport.handle_request(request)
  File "/home/airflow/.local/lib/python3.8/site-packages/httpx/_transports/default.py", line 218, in handle_request
    resp = self._pool.handle_request(req)
  File "/usr/local/lib/python3.8/contextlib.py", line 131, in __exit__
    self.gen.throw(type, value, traceback)
  File "/home/airflow/.local/lib/python3.8/site-packages/httpx/_transports/default.py", line 77, in map_httpcore_exceptions
    raise mapped_exc(message) from exc
httpx.ConnectError: [Errno -2] Name or service not known

During handling of the above exception, another exception occurred:

Traceback (most recent call last):
  File "/home/airflow/.local/lib/python3.8/site-packages/httpcore/_exceptions.py", line 10, in map_exceptions
    yield
  File "/home/airflow/.local/lib/python3.8/site-packages/httpcore/backends/sync.py", line 94, in connect_tcp
    sock = socket.create_connection(
  File "/usr/local/lib/python3.8/socket.py", line 787, in create_connection
    for res in getaddrinfo(host, port, 0, SOCK_STREAM):
  File "/usr/local/lib/python3.8/socket.py", line 918, in getaddrinfo
    for res in _socket.getaddrinfo(host, port, family, type, proto, flags):
socket.gaierror: [Errno -2] Name or service not known

During handling of the above exception, another exception occurred:

Traceback (most recent call last):
  File "/home/airflow/.local/lib/python3.8/site-packages/httpx/_transports/default.py", line 60, in map_httpcore_exceptions
    yield
  File "/home/airflow/.local/lib/python3.8/site-packages/httpx/_transports/default.py", line 218, in handle_request
    resp = self._pool.handle_request(req)
  File "/home/airflow/.local/lib/python3.8/site-packages/httpcore/_sync/connection_pool.py", line 253, in handle_request
    raise exc
  File "/home/airflow/.local/lib/python3.8/site-packages/httpcore/_sync/connection_pool.py", line 237, in handle_request
    response = connection.handle_request(request)
  File "/home/airflow/.local/lib/python3.8/site-packages/httpcore/_sync/connection.py", line 86, in handle_request
    raise exc
  File "/home/airflow/.local/lib/python3.8/site-packages/httpcore/_sync/connection.py", line 63, in handle_request
    stream = self._connect(request)
  File "/home/airflow/.local/lib/python3.8/site-packages/httpcore/_sync/connection.py", line 111, in _connect
    stream = self._network_backend.connect_tcp(**kwargs)
  File "/home/airflow/.local/lib/python3.8/site-packages/httpcore/backends/sync.py", line 94, in connect_tcp
    sock = socket.create_connection(
  File "/usr/local/lib/python3.8/contextlib.py", line 131, in __exit__
    self.gen.throw(type, value, traceback)
  File "/home/airflow/.local/lib/python3.8/site-packages/httpcore/_exceptions.py", line 14, in map_exceptions
    raise to_exc(exc)
httpcore.ConnectError: [Errno -2] Name or service not known

The above exception was the direct cause of the following exception:

Traceback (most recent call last):
  File "/home/airflow/.local/lib/python3.8/site-packages/openai/_base_client.py", line 955, in _request
    response = self._client.send(
  File "/home/airflow/.local/lib/python3.8/site-packages/httpx/_client.py", line 908, in send
    response = self._send_handling_auth(
  File "/home/airflow/.local/lib/python3.8/site-packages/httpx/_client.py", line 936, in _send_handling_auth
    response = self._send_handling_redirects(
  File "/home/airflow/.local/lib/python3.8/site-packages/httpx/_client.py", line 973, in _send_handling_redirects
    response = self._send_single_request(request)
  File "/home/airflow/.local/lib/python3.8/site-packages/httpx/_client.py", line 1009, in _send_single_request
    response = transport.handle_request(request)
  File "/home/airflow/.local/lib/python3.8/site-packages/httpx/_transports/default.py", line 218, in handle_request
    resp = self._pool.handle_request(req)
  File "/usr/local/lib/python3.8/contextlib.py", line 131, in __exit__
    self.gen.throw(type, value, traceback)
  File "/home/airflow/.local/lib/python3.8/site-packages/httpx/_transports/default.py", line 77, in map_httpcore_exceptions
    raise mapped_exc(message) from exc
httpx.ConnectError: [Errno -2] Name or service not known

The above exception was the direct cause of the following exception:

Traceback (most recent call last):
  File "/home/airflow/.local/lib/python3.8/site-packages/airflow/models/taskinstance.py", line 433, in _execute_task
    result = execute_callable(context=context, **execute_callable_kwargs)
  File "/home/airflow/.local/lib/python3.8/site-packages/airflow/operators/python.py", line 199, in execute
    return_value = self.execute_callable()
  File "/home/airflow/.local/lib/python3.8/site-packages/airflow/operators/python.py", line 216, in execute_callable
    return self.python_callable(*self.op_args, **self.op_kwargs)
  File "/opt/airflow/dags/youtube_comment_pipeline.py", line 115, in filter_with_openai
    res = client.chat.completions.create(
  File "/home/airflow/.local/lib/python3.8/site-packages/openai/_utils/_utils.py", line 279, in wrapper
    return func(*args, **kwargs)
  File "/home/airflow/.local/lib/python3.8/site-packages/openai/resources/chat/completions/completions.py", line 914, in create
    return self._post(
  File "/home/airflow/.local/lib/python3.8/site-packages/openai/_base_client.py", line 1242, in post
    return cast(ResponseT, self.request(cast_to, opts, stream=stream, stream_cls=stream_cls))
  File "/home/airflow/.local/lib/python3.8/site-packages/openai/_base_client.py", line 919, in request
    return self._request(
  File "/home/airflow/.local/lib/python3.8/site-packages/openai/_base_client.py", line 979, in _request
    return self._retry_request(
  File "/home/airflow/.local/lib/python3.8/site-packages/openai/_base_client.py", line 1057, in _retry_request
    return self._request(
  File "/home/airflow/.local/lib/python3.8/site-packages/openai/_base_client.py", line 979, in _request
    return self._retry_request(
  File "/home/airflow/.local/lib/python3.8/site-packages/openai/_base_client.py", line 1057, in _retry_request
    return self._request(
  File "/home/airflow/.local/lib/python3.8/site-packages/openai/_base_client.py", line 989, in _request
    raise APIConnectionError(request=request) from err
openai.APIConnectionError: Connection error.
[2025-04-14T08:21:17.923+0000] {taskinstance.py:1138} INFO - Marking task as FAILED. dag_id=youtube_comment_pipeline_us_stocks_daily, task_id=filter_with_openai, execution_date=20250413T080000, start_date=20250414T080002, end_date=20250414T082117
[2025-04-14T08:21:17.931+0000] {standard_task_runner.py:107} ERROR - Failed to execute job 417 for task filter_with_openai (Connection error.; 8647)
[2025-04-14T08:21:17.954+0000] {process_utils.py:79} INFO - Process psutil.Process(pid=8647, status='terminated', exitcode=1, started='08:00:01') (8647) terminated with exit code 1
